Workbook

Sheet Container 11
A1: No | B1: ASIN | C1: eBay IDs | D1: SKU | E1: Image Link | F1: Images | G1: Varmen Confirm | H1: Adams Listing | I1: Amazon | J1: Ebay | K1: Shopify | M1: =counta(D:D)-1 -> 19 | N1: =COUNTIF(I1:I100, TRUE) -> 11 | O1: =N1/M1 -> 0.57894737
A2: 1 | D2: LHXBTF40E27WH | E2: =VLOOKUP(D2,Sheet4!A2:B1000,2,0) -> https://dashboard.digitweblk.com/Productimages/23822.jpg | F2: =image(E2) | G2: TRUE | H2: TRUE | I2: FALSE | J2: FALSE | K2: FALSE
A3: 2 | D3: LHXBTF40E27BM | E3: =VLOOKUP(D3,Sheet4!A3:B1000,2,0) -> https://dashboard.digitweblk.com/Productimages/23823.jpg | F3: =image(E3) | G3: TRUE | H3: TRUE | I3: FALSE | J3: FALSE | K3: FALSE
A4: 3 | D4: LHXBTH50E27WH | E4: =VLOOKUP(D4,Sheet4!A4:B1000,2,0) -> https://dashboard.digitweblk.com/Productimages/23824.jpg | F4: =image(E4) | G4: TRUE | H4: TRUE | I4: FALSE | J4: FALSE | K4: FALSE
A5: 4 | D5: LHXBTH50E27BM | E5: =VLOOKUP(D5,Sheet4!A5:B1000,2,0) -> https://dashboard.digitweblk.com/Productimages/23825.jpg | F5: =image(E5) | G5: TRUE | H5: TRUE | I5: FALSE | J5: FALSE | K5: FALSE
A6: 5 | D6: LHXDE27WH | E6: =VLOOKUP(D6,Sheet4!A6:B1000,2,0) -> https://dashboard.digitweblk.com/Productimages/23742.jpg | F6: =image(E6) | G6: FALSE | H6: FALSE | I6: FALSE | J6: FALSE | K6: FALSE
A7: 6 | D7: LHXDE27BM | E7: =VLOOKUP(D7,Sheet4!A7:B1000,2,0) -> https://dashboard.digitweblk.com/Productimages/23741.jpg | F7: =image(E7) | G7: FALSE | H7: FALSE | I7: FALSE | J7: FALSE | K7: FALSE
A8: 7 | D8: PHXSH1PBRWH | E8: =VLOOKUP(D8,Sheet4!A8:B1000,2,0) -> https://dashboard.digitweblk.com/Productimages/23746.jpg | F8: =image(E8) | G8: FALSE | H8: FALSE | I8: FALSE | J8: FALSE | K8: FALSE
A9: 8 | D9: PHXSH1PBRBM | E9: =VLOOKUP(D9,Sheet4!A9:B1000,2,0) -> https://dashboard.digitweblk.com/Productimages/23740.jpg | F9: =image(E9) | G9: FALSE | H9: FALSE | I9: FALSE | J9: FALSE | K9: FALSE
A10: 9 | B10: B0GNZDWKJ6 B0GNZHGW4X B0GNZB4BPN B0GMHCHY7W B0GMHCM3ND | D10: LHXSHE27WH | E10: =VLOOKUP(D10,Sheet4!A10:B1000,2,0) -> https://dashboard.digitweblk.com/Productimages/23739.png | F10: =image(E10) | G10: TRUE | H10: TRUE | I10: TRUE | J10: FALSE | K10: FALSE | L10: dilani
A11: 10 | B11: B0GNZLCX15 B0GNYZMC5G B0GNYRK2GT B0GMHQTBSQ B0GMHFZ7C1 | D11: LHXSHE27BM | E11: =VLOOKUP(D11,Sheet4!A11:B1000,2,0) -> https://dashboard.digitweblk.com/Productimages/23738.png | F11: =image(E11) | G11: TRUE | H11: TRUE | I11: TRUE | J11: FALSE | K11: FALSE | L11: dilani
A12: 11 | B12: B0GQ9WT3WS B0GQBBSMWN B0GQ9FS6YG B0GQ9FTQYJ | D12: LHXCCE27WH | E12: =VLOOKUP(D12,Sheet4!A12:B1000,2,0) -> https://dashboard.digitweblk.com/Productimages/23743.png | F12: =image(E12) | G12: TRUE | H12: TRUE | I12: TRUE | J12: FALSE | K12: FALSE
A13: 12 | B13: B0GQBCXGST B0GQB28QMR B0GQ98ZNZ9 B0GQ94Y1LJ | D13: LHXCCE27BM | E13: =VLOOKUP(D13,Sheet4!A13:B1000,2,0) -> https://dashboard.digitweblk.com/Productimages/23744.png | F13: =image(E13) | G13: TRUE | H13: TRUE | I13: TRUE | J13: FALSE | K13: FALSE
A14: 13 | B14: B0GQ9XX4PM B0GQ9Z91YX B0GQ9GRVZZ B0GQ92JN6Y | D14: LHXCCE27RR | E14: =VLOOKUP(D14,Sheet4!A14:B1000,2,0) -> https://dashboard.digitweblk.com/Productimages/23745.png | F14: =image(E14) | G14: TRUE | H14: TRUE | I14: TRUE | J14: FALSE | K14: FALSE
A15: 14 | B15: B0GMGZJ8D5 B0GMG9FFYY | D15: LHXIM30B22WH | E15: =VLOOKUP(D15,Sheet4!A15:B1000,2,0) -> https://dashboard.digitweblk.com/Productimages/23737.jpg | F15: =image(E15) | G15: TRUE | H15: TRUE | I15: TRUE | J15: FALSE | K15: FALSE | L15: Theepana
A16: 15 | B16: B0GLXRPL51 B0GP16QFYT B0GNZRHMXW B0GNZNKDD1 B0GP139NG9 B0GNZDJZGV B0GNZ3DYVY B0GNZPZ4YM B0GNYVN663 B0GLZGC29N | D16: LHXWPE27PPWH | E16: =VLOOKUP(D16,Sheet4!A16:B1000,2,0) -> https://dashboard.digitweblk.com/Productimages/23736.jpg | F16: =image(E16) | G16: TRUE | H16: TRUE | I16: TRUE | J16: FALSE | K16: FALSE | L16: dilani
A17: 16 | B17: B0GR9GG6RY | D17: WJ018RB3PBM | E17: =VLOOKUP(D17,Sheet4!A17:B1000,2,0) -> https://dashboard.digitweblk.com/Productimages/23726.jpg | F17: =image(E17) | G17: TRUE | H17: TRUE | I17: TRUE | J17: FALSE | K17: FALSE | L17: Thojika
A18: 17 | B18: B0GLZ3VBC4 | D18: WJ018PC3PBM | E18: =VLOOKUP(D18,Sheet4!A18:B1000,2,0) -> https://dashboard.digitweblk.com/Productimages/23727.jpeg | F18: =image(E18) | G18: TRUE | H18: TRUE | I18: TRUE | J18: FALSE | K18: FALSE | L18: Preethi
A19: 18 | B19: B0GNSJ14M4 | D19: WJB603BM | E19: =VLOOKUP(D19,Sheet4!A19:B1000,2,0) -> https://dashboard.digitweblk.com/Productimages/23728.jpg | F19: =image(E19) | G19: TRUE | H19: TRUE | I19: TRUE | J19: FALSE | K19: FALSE | L19: Preethi
A20: 19 | B20: B0DN687J6W | D20: WJM6332BM | E20: =VLOOKUP(D20,Sheet4!A20:B1000,2,0) -> https://dashboard.digitweblk.com/Productimages/23729.jpg | F20: =image(E20) | G20: TRUE | H20: TRUE | I20: TRUE | J20: FALSE | K20: FALSE | L20: Preethi

Sheet Container 12
A1: No | B1: ASIN | C1: eBay IDs | D1: SKU | E1: Image Link | F1: Images | G1: Varmen Confirm | H1: Adams Listing | I1: Amazon | J1: Ebay | K1: Shopify | M1: =counta(D:D)-1 -> 82 | N1: =COUNTIF(I1:I100, TRUE) -> 47 | O1: =N1/M1 -> 0.57317073 | Q1: ASINs
A2: 1 | B2: B0GNYYQ542 B0GNZ9K56X | D2: LSGLBG145AR | E2: https://dashboard.digitweblk.com/Productimages/23682.jpg | F2: =IMAGE(E2:E994) | G2: TRUE | H2: TRUE | I2: TRUE | J2: FALSE | K2: FALSE | L2: Waiting for the image varification | M2: DILANI | Q2: B07WP51SL6 | S2: colour not confirmed
A3: 2 | B3: B0GQ44NJ32 B0GQZBBJFX | D3: LSGLBT200PU | E3: https://dashboard.digitweblk.com/Productimages/23678.jpg | F3: =IMAGE(E3:E995) | G3: TRUE | H3: TRUE | I3: TRUE | J3: FALSE | K3: FALSE | L3: Waiting for the image varification | Q3: B0GQZLFJRQ
A4: 3 | B4: B0GQ48BNBZ | D4: LSGLSC115AR | E4: https://dashboard.digitweblk.com/Productimages/23664.jpg | F4: =IMAGE(E4:E996) | G4: TRUE | H4: TRUE | I4: TRUE | J4: FALSE | K4: FALSE | L4: Waiting for the image varification | Q4: B0GQZ9RGBD
A5: 4 | B5: B07WP51SL6 B0GQZLFJRQ B0GQZ9RGBD | D5: LSGLBC160AR | E5: https://dashboard.digitweblk.com/Productimages/23685.jpeg | F5: =IMAGE(E5:E997) | G5: TRUE | H5: TRUE | I5: TRUE | J5: FALSE | K5: FALSE | Q5: B0GQ44NJ32
A6: 5 | B6: B0GNZ7CYNF B0GNZ9Q62W | D6: LSGLULSG | E6: https://dashboard.digitweblk.com/Productimages/23606.jpg | F6: =IMAGE(E6:E998) | G6: TRUE | H6: TRUE | I6: TRUE | J6: FALSE | K6: FALSE | L6: Waiting for the image varification | Q6: B0GQZBBJFX
A7: 6 | B7: B0GLZ4FC6Z B0GMD7MTCJ | D7: LSGLDC160AS | E7: https://dashboard.digitweblk.com/Productimages/23684.jpg | F7: =IMAGE(E7:E999) | G7: TRUE | H7: TRUE | I7: TRUE | J7: FALSE | K7: FALSE | L7: Image correction needed | Q7: B0GQ48BNBZ
A8: 7 | B8: B0GNQZDVXL | D8: LSGLBH300WS | E8: https://dashboard.digitweblk.com/Productimages/23683.jpg | F8: =IMAGE(E8:E1000) | G8: TRUE | H8: TRUE | I8: TRUE | J8: FALSE | K8: FALSE | Q8: B07WP51SL6
A9: 8 | B9: B0GQZLYNDZ B0GQZLYNDZ | D9: LSGLWB125TN | E9: https://dashboard.digitweblk.com/Productimages/23677.jpg | F9: =IMAGE(E9:E1001) | G9: TRUE | H9: TRUE | I9: TRUE | J9: FALSE | K9: FALSE | L9: Waiting for the image varification | Q9: B0GQZLFJRQ
A10: 9 | B10: B0GNR6NQXD | D10: LSGLBG130WH | E10: https://dashboard.digitweblk.com/Productimages/23686.jpg | F10: =IMAGE(E10:E1002) | G10: TRUE | H10: TRUE | I10: TRUE | J10: FALSE | K10: FALSE | Q10: B0GQZ9RGBD
A11: 10 | B11: B0GLNWFGQ7 B0GMCRC482 B0GQZLBH4Y | D11: LSGLWM200YC | E11: https://dashboard.digitweblk.com/Productimages/23671.jpg | F11: =IMAGE(E11:E1003) | G11: TRUE | H11: TRUE | I11: TRUE | J11: FALSE | K11: FALSE | Q11: B0GNZ7CYNF
A12: 11 | B12: B0GMCRC482 B0GLNWFGQ7 B0GRGCH2JG | D12: LSGLWS180YC | E12: https://dashboard.digitweblk.com/Productimages/23672.jpg | F12: =IMAGE(E12:E1004) | G12: TRUE | H12: TRUE | I12: TRUE | J12: FALSE | K12: FALSE | Q12: B0GNZ9Q62W
A13: 12 | B13: B0GMD4R26Y B0GLZ4SY9Q | D13: LSGLCP120SY | E13: https://dashboard.digitweblk.com/Productimages/23670.jpg | F13: =IMAGE(E13:E1005) | G13: TRUE | H13: TRUE | I13: TRUE | J13: FALSE | K13: FALSE | L13: Image correction needed | Q13: B0GLZ4FC6Z
A14: 13 | B14: B0GQ477V54 | D14: LSGLLF170AR | E14: https://dashboard.digitweblk.com/Productimages/23663.jpg | F14: =IMAGE(E14:E1006) | G14: TRUE | H14: TRUE | I14: TRUE | J14: FALSE | K14: FALSE | L14: Waiting for the image varification | Q14: B0GMD7MTCJ
A15: 14 | B15: B0GNRHD755 | D15: LSGLBH150WS | E15: https://dashboard.digitweblk.com/Productimages/23673.jpg | F15: =IMAGE(E15:E1007) | G15: TRUE | H15: TRUE | I15: TRUE | J15: FALSE | K15: FALSE | Q15: B0GNQZDVXL
A16: 15 | B16: B0GLGQ78BC B0GLFZ9BSJ | D16: LSGLFP245BR | E16: https://dashboard.digitweblk.com/Productimages/23676.jpg | F16: =IMAGE(E16:E1008) | G16: TRUE | H16: TRUE | I16: TRUE | J16: FALSE | K16: FALSE | Q16: B0GQZLYNDZ
A17: 16 | B17: B0GLGXQ7CD B0GLGGJD2R | D17: LSGLFP245GR | E17: https://dashboard.digitweblk.com/Productimages/23666.jpg | F17: =IMAGE(E17:E1009) | G17: TRUE | H17: TRUE | I17: TRUE | J17: FALSE | K17: FALSE | Q17: B0GQZLYNDZ
A18: 17 | B18: B0GLGZDTH6 B0GLGLH64Z | D18: LSGLFP245BL | E18: https://dashboard.digitweblk.com/Productimages/23674.jpg | F18: =IMAGE(E3:E994) | G18: TRUE | H18: TRUE | I18: TRUE | J18: FALSE | K18: FALSE | Q18: B0GNR6NQXD
A19: 18 | B19: B0GLGSZJWJ B0GLGB3M6Q | D19: LSGLFP245PU | E19: https://dashboard.digitweblk.com/Productimages/23665.jpg | F19: =IMAGE(E4:E995) | G19: TRUE | H19: TRUE | I19: TRUE | J19: FALSE | K19: FALSE | Q19: B0GLNWFGQ7
A20: 19 | B20: B0GLYS5QCP B0GLZ2SYN4 B0GMGV1PMJ | D20: PLTRBC | E20: https://dashboard.digitweblk.com/Productimages/23658.png | F20: =IMAGE(E5:E996) | G20: TRUE | H20: TRUE | I20: TRUE | J20: FALSE | K20: FALSE | Q20: B0GMCRC482
A21: 20 | B21: B0GLZ42JJD B0GLYWV3LG B0GMH9D8H8 | D21: PLTRBM | E21: https://dashboard.digitweblk.com/Productimages/23657.jpeg | F21: =IMAGE(E6:E997) | G21: TRUE | H21: TRUE | I21: TRUE | J21: FALSE | K21: FALSE | Q21: B0GQZLBH4Y
A22: 21 | B22: B0GLYZ41VT B0GLYT7GQY | D22: PLTRULBC | E22: https://dashboard.digitweblk.com/Productimages/23669.jpeg | F22: =IMAGE(E7:E998) | G22: TRUE | H22: TRUE | I22: TRUE | J22: FALSE | K22: FALSE | M22: Theepana | N22: size details check | Q22: B0GMCRC482
A23: 22 | B23: B0GLZ888M6 B0GLYWJ4WL B0GMGKQPQP | D23: PLTRULBM | E23: https://dashboard.digitweblk.com/Productimages/23668.jpeg | F23: =IMAGE(E8:E999) | G23: TRUE | H23: TRUE | I23: TRUE | J23: FALSE | K23: FALSE | M23: Theepana | N23: size details check | Q23: B0GLNWFGQ7
A24: 23 | B24: B0GLPHBN8D B0GLNBSJMP | D24: PL4HRR | E24: https://dashboard.digitweblk.com/Productimages/23621.jpg | F24: =IMAGE(E9:E1000) | G24: TRUE | H24: TRUE | I24: TRUE | J24: FALSE | K24: FALSE | Q24: B0GRGCH2JG
A25: 24 | B25: B0GLPJH67X B0GLNHSJZ8 | D25: PL4HBM | E25: https://dashboard.digitweblk.com/Productimages/23620.jpg | F25: =IMAGE(E10:E1001) | G25: TRUE | H25: TRUE | I25: TRUE | J25: FALSE | K25: FALSE | Q25: B0GMD4R26Y
A26: 25 | B26: B0GLPLNXXC B0GLNHVVKS | D26: PL4HBC | E26: https://dashboard.digitweblk.com/Productimages/23619.jpg | F26: =IMAGE(E11:E1002) | G26: TRUE | H26: TRUE | I26: TRUE | J26: FALSE | K26: FALSE | Q26: B0GLZ4SY9Q
A27: 26 | B27: B0GMZVHF2T B0GN19RY8V | D27: WLFS220RR | E27: https://dashboard.digitweblk.com/Productimages/23618.jpeg | F27: =IMAGE(E12:E1003) | G27: TRUE | H27: TRUE | I27: TRUE | J27: FALSE | K27: FALSE | Q27: B0GQ477V54
A28: 27 | B28: B0GMZVR3R9 B0GMZY55ZG | D28: WLFS220BS | E28: https://dashboard.digitweblk.com/Productimages/23787.jpg | F28: =IMAGE(E13:E1004) | G28: TRUE | H28: TRUE | I28: TRUE | J28: FALSE | K28: FALSE | Q28: B0GNRHD755
A29: 28 | B29: B0GMZPVPNR B0GN1855BJ | D29: WLFS220BC | E29: https://dashboard.digitweblk.com/Productimages/23786.jpg | F29: =IMAGE(E14:E1005) | G29: TRUE | H29: TRUE | I29: TRUE | J29: FALSE | K29: FALSE | Q29: B0GLGQ78BC
A30: 29 | B30: B0GR625MB7 | D30: LSRH260AZ | E30: https://dashboard.digitweblk.com/Productimages/23659.jpg | F30: =IMAGE(E15:E1006) | G30: TRUE | H30: TRUE | I30: TRUE | J30: FALSE | K30: FALSE | Q30: B0GLFZ9BSJ
A31: 30 | B31: B0GR5Z5PX3 | D31: LSRT120AZ | E31: https://dashboard.digitweblk.com/Productimages/23660.jpeg | F31: =IMAGE(E16:E1007) | G31: TRUE | H31: TRUE | I31: TRUE | J31: FALSE | K31: FALSE | Q31: B0GLGXQ7CD
A32: 31 | B32: B0GR6FKHN1 | D32: LSRD260AZ | E32: https://dashboard.digitweblk.com/Productimages/23661.jpeg | F32: =IMAGE(E17:E1008) | G32: TRUE | H32: TRUE | I32: TRUE | J32: FALSE | K32: FALSE | Q32: B0GLGGJD2R
A33: 32 | B33: B0GP749K4P B0GP77P5Z5 B0GP87YX8W B0GP7RHSVG B0GP8C3TRW B0GP84PWQN B0GP73VLM8 B0GP6YD78R B0GP719CDX B0GP7TLRLZ | D33: LHPVHRE27WH | E33: https://dashboard.digitweblk.com/Productimages/23713.jpeg | F33: =IMAGE(E18:E1009) | G33: TRUE | H33: TRUE | I33: TRUE | J33: FALSE | K33: FALSE | Q33: B0GLGZDTH6
A34: 33 | D34: LHPVC1E27WH | E34: https://dashboard.digitweblk.com/Productimages/23715.jpeg | F34: =IMAGE(E19:E1010) | G34: TRUE | H34: TRUE | I34: FALSE | J34: FALSE | K34: FALSE | Q34: B0GLGLH64Z
A35: 34 | D35: LHPVWBE27WB | E35: https://dashboard.digitweblk.com/Productimages/23714.png | F35: =IMAGE(E19:E994) | G35: FALSE | H35: TRUE | I35: FALSE | J35: FALSE | K35: FALSE | Q35: B0GLGSZJWJ
A36: 35 | D36: LHPVC2E27WH | E36: https://dashboard.digitweblk.com/Productimages/23716.png | F36: =IMAGE(E20:E995) | G36: FALSE | H36: TRUE | I36: FALSE | J36: FALSE | K36: FALSE | Q36: B0GLGB3M6Q
A37: 36 | D37: LHPVGBWH | E37: https://dashboard.digitweblk.com/Productimages/23711.png | F37: =IMAGE(E21:E996) | G37: TRUE | H37: TRUE | I37: FALSE | J37: FALSE | K37: FALSE | Q37: B0GLYS5QCP
A38: 37 | D38: LHPVSCE27WH | E38: https://dashboard.digitweblk.com/Productimages/23712.jpeg | F38: =IMAGE(E22:E997) | G38: TRUE | H38: TRUE | I38: FALSE | J38: FALSE | K38: FALSE | Q38: B0GLZ2SYN4
A39: 38 | D39: SWHBSP1OSWH | E39: https://dashboard.digitweblk.com/Productimages/23708.png | F39: =IMAGE(E23:E998) | G39: TRUE | H39: TRUE | I39: FALSE | J39: FALSE | K39: FALSE | L39: AH | Q39: B0GMGV1PMJ
A40: 39 | D40: SWHBPB1OSWB | E40: https://dashboard.digitweblk.com/Productimages/23710.png | F40: =IMAGE(E24:E999) | G40: TRUE | H40: TRUE | I40: FALSE | J40: FALSE | K40: FALSE | L40: AH | Q40: B0GLZ42JJD
...

Sheet Container 13
A1: No | B1: ASIN | C1: eBay IDs | D1: SKU | E1: Image Link | F1: Images | G1: Note | H1: Varmen Confirm | I1: Adams Listing | J1: Amazon | K1: Ebay | L1: Shopify | M1: =counta(D:D)-1 -> 33 | N1: =COUNTIF(J1:J100, TRUE) -> 14 | O1: =N1/M1 -> 0.42424242
A2: 1 | D2: WCFRO3DCPBBM | E2: =vlookup(D2,Sheet4!A:B,2,false) -> https://dashboard.digitweblk.com/Productimages/23793.png | F2: =IMAGE(E2:E17) | G2: Pre pack product , already have listings | H2: FALSE | I2: FALSE | J2: FALSE | K2: FALSE
A3: 2 | D3: WCFRO3LNPYBM | E3: =vlookup(D3,Sheet4!A:B,2,false) -> https://dashboard.digitweblk.com/Productimages/23789.png | F3: =IMAGE(E3:E18) | G3: Pre pack product , already have listings | H3: FALSE | I3: FALSE | J3: FALSE | K3: FALSE
A4: 3 | D4: WCFRE3LNPYBM | E4: =vlookup(D4,Sheet4!A:B,2,false) -> https://dashboard.digitweblk.com/Productimages/23790.png | F4: =IMAGE(E4:E19) | G4: Pre pack product , already have listings | H4: FALSE | I4: FALSE | J4: FALSE | K4: FALSE
A5: 4 | D5: WCFRO3WDPBBM | E5: =vlookup(D5,Sheet4!A:B,2,false) -> https://dashboard.digitweblk.com/Productimages/23791.png | F5: =IMAGE(E5:E20) | G5: Pre pack product , already have listings | H5: FALSE | I5: FALSE | J5: FALSE | K5: FALSE
A6: 5 | D6: WCFRO3WDPYBM | E6: =vlookup(D6,Sheet4!A:B,2,false) -> https://dashboard.digitweblk.com/Productimages/23792.png | F6: =IMAGE(E6:E21) | G6: Pre pack product , already have listings | H6: FALSE | I6: FALSE | J6: FALSE | K6: FALSE
A7: 6 | D7: WCFRO3DCPBBM | E7: =vlookup(D7,Sheet4!A:B,2,false) -> https://dashboard.digitweblk.com/Productimages/23793.png | F7: =IMAGE(E7:E22) | G7: Pre pack product , already have listings | H7: FALSE | I7: FALSE | J7: FALSE | K7: FALSE
A8: 7 | B8: B0GLR34G2Q B0GLQ6PB3J | D8: LSCY290DWH | E8: =vlookup(D8,Sheet4!A:B,2,false) -> https://dashboard.digitweblk.com/Productimages/23644.jpg | F8: =IMAGE(E8:E23) | H8: TRUE | I8: TRUE | J8: TRUE | K8: FALSE
A9: 8 | B9: B0GLR16H5P B0GLQ8J3WP | D9: LSCY290DGD | E9: =vlookup(D9,Sheet4!A:B,2,false) -> https://dashboard.digitweblk.com/Productimages/23642.jpg | F9: =IMAGE(E9:E25) | H9: TRUE | I9: TRUE | J9: TRUE | K9: FALSE
A10: 9 | B10: B0GLRT4KXS B0GLPZPXC1 | D10: LSCY290DNB | E10: =vlookup(D10,Sheet4!A:B,2,false) -> https://dashboard.digitweblk.com/Productimages/23641.jpg | F10: =IMAGE(E10:E26) | H10: TRUE | I10: TRUE | J10: TRUE | K10: FALSE
A11: 10 | B11: B0GLR5F57B B0GLQBYTGK | D11: LSCY290DOR | E11: =vlookup(D11,Sheet4!A:B,2,false) -> https://dashboard.digitweblk.com/Productimages/23640.jpg | F11: =IMAGE(E11:E27) | H11: TRUE | I11: TRUE | J11: TRUE | K11: FALSE
A12: 11 | B12: B0GLR9TLTX B0GLQ72BZ8 | D12: LSCY290DBU | E12: =vlookup(D12,Sheet4!A:B,2,false) -> https://dashboard.digitweblk.com/Productimages/23639.jpg | F12: =IMAGE(E12:E28) | H12: TRUE | I12: TRUE | J12: TRUE | K12: FALSE
A13: 12 | B13: B0GLQXPNCP B0GLQBNF6L | D13: LSCY290DRE | E13: =vlookup(D13,Sheet4!A:B,2,false) -> https://dashboard.digitweblk.com/Productimages/23638.jpg | F13: =IMAGE(E13:E29) | H13: TRUE | I13: TRUE | J13: TRUE | K13: FALSE
A14: 13 | B14: B0GLQTHFPB B0GLQ2N3MN | D14: LSCY290DGY | E14: =vlookup(D14,Sheet4!A:B,2,false) -> https://dashboard.digitweblk.com/Productimages/23637.jpg | F14: =IMAGE(E14:E30) | H14: TRUE | I14: TRUE | J14: TRUE | K14: FALSE
A15: 14 | B15: B0GLQYRR7B B0GLQC394Y | D15: LSCY290DYE | E15: =vlookup(D15,Sheet4!A:B,2,false) -> https://dashboard.digitweblk.com/Productimages/23636.jpg | F15: =IMAGE(E15:E31) | H15: TRUE | I15: TRUE | J15: TRUE | K15: FALSE
A16: 15 | B16: B0GLRKC9L5 B0GLQ245L8 | D16: LSCY290DCB | E16: =vlookup(D16,Sheet4!A:B,2,false) -> https://dashboard.digitweblk.com/Productimages/23635.jpg | F16: =IMAGE(E16:E32) | H16: TRUE | I16: TRUE | J16: TRUE | K16: FALSE
A17: 16 | B17: B0GLQZ7L1Z B0GLPXD3LQ | D17: LSCY290DBI | E17: =vlookup(D17,Sheet4!A:B,2,false) -> https://dashboard.digitweblk.com/Productimages/23634.jpg | F17: =IMAGE(E17:E33) | H17: TRUE | I17: TRUE | J17: TRUE | K17: FALSE
A18: 17 | B18: B0GLR6RM6P B0GLQ28C6T | D18: LSCY290DBT | E18: =vlookup(D18,Sheet4!A:B,2,false) -> https://dashboard.digitweblk.com/Productimages/23633.jpg | F18: =IMAGE(E18:E34) | H18: TRUE | I18: TRUE | J18: TRUE | K18: FALSE
A19: 18 | D19: LSFSDC1BM | E19: =vlookup(D19,Sheet4!A:B,2,false) -> https://dashboard.digitweblk.com/Productimages/23616.jpg | F19: =IMAGE(E19:E35) | H19: TRUE | I19: TRUE | J19: FALSE | K19: FALSE | M19: Theepana
A20: 19 | D20: LSGL9015GY | E20: =vlookup(D20,Sheet4!A:B,2,false) -> https://dashboard.digitweblk.com/Productimages/23604.jpg | F20: =IMAGE(E20) | H20: TRUE | I20: TRUE | J20: FALSE | K20: FALSE | M20: No price
A21: 20 | D21: LSGL606CL | E21: =vlookup(D21,Sheet4!A:B,2,false) -> https://dashboard.digitweblk.com/Productimages/23605.jpg | F21: =IMAGE(E21) | H21: FALSE | I21: TRUE | J21: FALSE | K21: FALSE
A22: 21 | B22: B0GTMZWFCD B0GTMJFSTP B0GTMQW1WF MERCHANT B0GTMT5N9B B0GTJ5P1KW B0GTHT26DV B0GTHJQKPG B0GTJ1BS3K | D22: LSGL10014CL | E22: =vlookup(D22,Sheet4!A:B,2,false) -> https://dashboard.digitweblk.com/Productimages/23607.jpg | F22: =IMAGE(E22) | H22: TRUE | I22: TRUE | J22: FALSE | K22: FALSE
A23: 22 | D23: LSGL6016CL | E23: =vlookup(D23,Sheet4!A:B,2,false) -> https://dashboard.digitweblk.com/Productimages/23610.jpg | F23: =IMAGE(E23) | H23: FALSE | I23: TRUE | J23: FALSE | K23: FALSE
A24: 23 | B24: B0GT4SFWFY B0GT4GWLHW | D24: LSGL9015CL | E24: =vlookup(D24,Sheet4!A:B,2,false) -> https://dashboard.digitweblk.com/Productimages/23613.jpg | F24: =IMAGE(E24) | H24: TRUE | I24: TRUE | J24: FALSE | K24: FALSE
A25: 24 | B25: B0CS6MSRCZ | D25: LSGL7512CL | E25: =vlookup(D25,Sheet4!A:B,2,false) -> https://dashboard.digitweblk.com/Productimages/23615.jpg | F25: =IMAGE(E25) | H25: TRUE | I25: TRUE | J25: FALSE | K25: FALSE
A26: 25 | B26: B0GR8RKQ23 B0GQZLFJRQ B0GR893H5P | D26: LSGL10012AR | E26: =vlookup(D26,Sheet4!A:B,2,false) -> https://dashboard.digitweblk.com/Productimages/23614.jpg | F26: =IMAGE(E26) | H26: TRUE | I26: TRUE | J26: FALSE | K26: FALSE
A27: 26 | D27: LSGL15014CL | E27: =vlookup(D27,Sheet4!A:B,2,false) -> https://dashboard.digitweblk.com/Productimages/23612.jpg | F27: =IMAGE(E27) | H27: FALSE | I27: TRUE | J27: FALSE | K27: FALSE
A28: 27 | D28: LSGL9015WH | E28: =vlookup(D28,Sheet4!A:B,2,false) -> https://dashboard.digitweblk.com/Productimages/23611.jpg | F28: =IMAGE(E28) | H28: TRUE | I28: TRUE | J28: FALSE | K28: FALSE
A29: 28 | B29: B0GSRQM519 B0GSR3M9RD B0GSG2GQ99 B0GSFB5MT6 | D29: LSGLULCL | E29: =vlookup(D29,Sheet4!A:B,2,false) -> https://dashboard.digitweblk.com/Productimages/23609.jpg | F29: =IMAGE(E29) | H29: TRUE | I29: TRUE | J29: FALSE | K29: FALSE | M29: dilani | N29: size details check
A30: 29 | D30: LSGLTNAR | E30: =vlookup(D30,Sheet4!A:B,2,false) -> https://dashboard.digitweblk.com/Productimages/23608.jpg | F30: =IMAGE(E30) | H30: FALSE | I30: FALSE | J30: FALSE | K30: FALSE
A31: 30 | B31: B0GNZ7CYNF B0GNZ9Q62W B0GNZ7CYNF | D31: LSGLULSG | E31: =vlookup(D31,Sheet4!A:B,2,false) -> https://dashboard.digitweblk.com/Productimages/23606.jpg | F31: =IMAGE(E31) | H31: TRUE | I31: TRUE | J31: TRUE | K31: FALSE
B32: B0GMW9YWCV B0GMW7JNRP B0GMVXCZ14 B0GMVW1FKR B0GLZZ7RTQ B0GLZDQ311 B0GLZB6539 B0GLZ4GN7P B0GLXBQ1FT B0GLX6PHSN | D32: LSHM240BG | E32: =vlookup(D32,Sheet4!A:B,2,false) -> https://dashboard.digitweblk.com/Productimages/23617.jpeg | F32: =IMAGE(E32) | H32: TRUE | I32: TRUE | J32: TRUE
B33: B0GMRCLVCX B0GMR5VGVG B0GMRH36DQ B0GMPDVMCB B0GMP89W89 B0GMPBX8D6 | D33: LSFT220BW | E33: =vlookup(D33,Sheet4!A:B,2,false) -> https://dashboard.digitweblk.com/Productimages/23816.jpg | F33: =IMAGE(E33) | H33: TRUE | I33: TRUE | J33: TRUE | M33: size details check
D34: WSWTCBM | E34: =vlookup(D34,Sheet4!A:B,2,false) -> https://dashboard.digitweblk.com/Productimages/23821.jpg | F34: =IMAGE(E34) | H34: TRUE | I34: TRUE | J34: FALSE

Sheet Container 14
A1: No | B1: ASIN | C1: eBay IDs | D1: SKU | E1: Image Link | F1: Images | G1: Varmen Confirm | H1: Adams Listing | I1: Amazon | J1: eBay | K1: Shopify | L1: delivery date 26/02/2026 | M1: =counta(D:D)-1 -> 35 | N1: =COUNTIF(I1:I100, TRUE) -> 8 | O1: =N1/M1 -> 0.22857143
A2: 1 | D2: WCBTC100FG | E2: =VLOOKUP(D2,Sheet4!A2:B1000,2,0) -> https://dashboard.digitweblk.com/Productimages/23703.jpg | F2: =IMAGE(E2:E1000) | G2: FALSE | H2: TRUE | I2: FALSE | J2: FALSE | K2: FALSE
A3: 2 | D3: WCBTC120FG | E3: =VLOOKUP(D3,Sheet4!A3:B1000,2,0) -> https://dashboard.digitweblk.com/Productimages/23704.jpg | F3: =IMAGE(E3:E1001) | G3: FALSE | H3: TRUE | I3: FALSE | J3: FALSE | K3: FALSE
A4: 3 | D4: WCBTC140FG | E4: =VLOOKUP(D4,Sheet4!A4:B1000,2,0) -> https://dashboard.digitweblk.com/Productimages/23705.jpg | F4: =IMAGE(E4:E1002) | G4: FALSE | H4: TRUE | I4: FALSE | J4: FALSE | K4: FALSE
A5: 4 | D5: WCBSF120FG | E5: =VLOOKUP(D5,Sheet4!A5:B1000,2,0) -> https://dashboard.digitweblk.com/Productimages/23707.jpg | F5: =IMAGE(E5:E1003) | G5: FALSE | H5: TRUE | I5: FALSE | J5: FALSE | K5: FALSE
A6: 5 | D6: WCBSF90FG | E6: =VLOOKUP(D6,Sheet4!A6:B1000,2,0) -> https://dashboard.digitweblk.com/Productimages/23706.jpg | F6: =IMAGE(E6:E1004) | G6: FALSE | H6: TRUE | I6: FALSE | J6: FALSE | K6: FALSE
A7: 6 | D7: WCBTC100FG | E7: =VLOOKUP(D7,Sheet4!A7:B1000,2,0) -> https://dashboard.digitweblk.com/Productimages/23703.jpg | F7: =IMAGE(E7:E1005) | G7: FALSE | H7: TRUE | I7: FALSE | J7: FALSE | K7: FALSE
A8: 7 | D8: WCBTC120FG | E8: =VLOOKUP(D8,Sheet4!A8:B1000,2,0) -> https://dashboard.digitweblk.com/Productimages/23704.jpg | F8: =IMAGE(E8:E1006) | G8: FALSE | H8: TRUE | I8: FALSE | J8: FALSE | K8: FALSE
A9: 8 | D9: WCBTC140FG | E9: =VLOOKUP(D9,Sheet4!A9:B1000,2,0) -> https://dashboard.digitweblk.com/Productimages/23705.jpg | F9: =IMAGE(E9:E1007) | G9: FALSE | H9: TRUE | I9: FALSE | J9: FALSE | K9: FALSE
A10: 9 | D10: WCBSF120FG | E10: =VLOOKUP(D10,Sheet4!A10:B1000,2,0) -> https://dashboard.digitweblk.com/Productimages/23707.jpg | F10: =IMAGE(E10:E1008) | G10: FALSE | H10: TRUE | I10: FALSE | J10: FALSE | K10: FALSE
A11: 10 | D11: WCBSF90FG | E11: =VLOOKUP(D11,Sheet4!A11:B1000,2,0) -> https://dashboard.digitweblk.com/Productimages/23706.jpg | F11: =IMAGE(E11:E1009) | G11: FALSE | H11: TRUE | I11: FALSE | J11: FALSE | K11: FALSE
A12: 11 | B12: B0GQZ5K8FZ B0GQTGMKGC | D12: LSFT255GR | E12: =VLOOKUP(D12,Sheet4!A12:B1000,2,0) -> https://dashboard.digitweblk.com/Productimages/23698.png | F12: =IMAGE(E12:E1010) | G12: FALSE | H12: TRUE | I12: TRUE | J12: FALSE | K12: FALSE
A13: 12 | B13: B0GQTDRCM6 | D13: LSFT255GY | E13: =VLOOKUP(D13,Sheet4!A13:B1000,2,0) -> https://dashboard.digitweblk.com/Productimages/23697.png | F13: =IMAGE(E13:E1011) | G13: FALSE | H13: TRUE | I13: TRUE | J13: FALSE | K13: FALSE
A14: 13 | B14: B0GQZ28WNN B0GQTKCX4S | D14: LSFT255BT | E14: =VLOOKUP(D14,Sheet4!A14:B1000,2,0) -> https://dashboard.digitweblk.com/Productimages/23696.png | F14: =IMAGE(E14:E1012) | G14: FALSE | H14: TRUE | I14: TRUE | J14: FALSE | K14: FALSE
A15: 14 | B15: B0GQZ9N8MG B0GQTG8JTS | D15: LSFT255CB | E15: =VLOOKUP(D15,Sheet4!A15:B1000,2,0) -> https://dashboard.digitweblk.com/Productimages/23695.png | F15: =IMAGE(E15:E1013) | G15: FALSE | H15: TRUE | I15: TRUE | J15: FALSE | K15: FALSE
A16: 15 | B16: B0GQZH3M9D B0GQTHNP61 | D16: LSFT255BD | E16: =VLOOKUP(D16,Sheet4!A16:B1000,2,0) -> https://dashboard.digitweblk.com/Productimages/23694.png | F16: =IMAGE(E16:E1014) | G16: FALSE | H16: TRUE | I16: TRUE | J16: FALSE | K16: FALSE
A17: 16 | B17: B0GQYZ8GN4 B0GQTMZXJ2 | D17: LSFT255RE | E17: =VLOOKUP(D17,Sheet4!A17:B1000,2,0) -> https://dashboard.digitweblk.com/Productimages/23692.png | F17: =IMAGE(E17:E1015) | G17: FALSE | H17: TRUE | I17: TRUE | J17: FALSE | K17: FALSE
A18: 17 | B18: B0GQZKM8GB B0GQTD87KL | D18: LSFT255BI | E18: =VLOOKUP(D18,Sheet4!A18:B1000,2,0) -> https://dashboard.digitweblk.com/Productimages/23691.png | F18: =IMAGE(E18:E1016) | G18: FALSE | H18: TRUE | I18: TRUE | J18: FALSE | K18: FALSE
A19: 18 | B19: B0GQZFPN3X B0GQT8XQTL | D19: LSFT255WH | E19: =VLOOKUP(D19,Sheet4!A19:B1000,2,0) -> https://dashboard.digitweblk.com/Productimages/23690.png | F19: =IMAGE(E19:E1017) | G19: FALSE | H19: TRUE | I19: TRUE | J19: FALSE | K19: FALSE
A20: 19 | D20: LHTMPSE27BM | E20: =VLOOKUP(D20,Sheet4!A20:B1000,2,0) -> https://dashboard.digitweblk.com/Productimages/23700.png | F20: =IMAGE(E20:E1018) | G20: FALSE | H20: FALSE | I20: FALSE | J20: FALSE | K20: FALSE
A21: 20 | D21: LHTMCE27BM | E21: =VLOOKUP(D21,Sheet4!A21:B1000,2,0) -> https://dashboard.digitweblk.com/Productimages/23699.jpg | F21: =IMAGE(E21:E1019) | G21: FALSE | H21: FALSE | I21: FALSE | J21: FALSE | K21: FALSE
A22: 21 | D22: PHSH2BMTBM | E22: =VLOOKUP(D22,Sheet4!A22:B1000,2,0) -> https://dashboard.digitweblk.com/Productimages/23702.png | F22: =IMAGE(E22:E1020) | G22: FALSE | H22: FALSE | I22: FALSE | J22: FALSE | K22: FALSE
A23: 22 | D23: PHSH2BMTYB | E23: =VLOOKUP(D23,Sheet4!A23:B1000,2,0) -> https://dashboard.digitweblk.com/Productimages/23701.png | F23: =IMAGE(E23:E1021) | G23: FALSE | H23: FALSE | I23: FALSE | J23: FALSE | K23: FALSE
A24: 23 | D24: PSL45P05OS2HYBM | E24: =VLOOKUP(D24,Sheet4!A24:B1000,2,0) -> https://dashboard.digitweblk.com/Productimages/23651.jpg | F24: =IMAGE(E24:E1022) | G24: FALSE | H24: FALSE | I24: FALSE | J24: FALSE | K24: FALSE
A25: 24 | D25: PSL4P25OS3HNBM | E25: =VLOOKUP(D25,Sheet4!A25:B1000,2,0) -> https://dashboard.digitweblk.com/Productimages/23652.jpg | F25: =IMAGE(E25:E1023) | G25: FALSE | H25: FALSE | I25: FALSE | J25: FALSE | K25: FALSE
A26: 25 | D26: PSL45P05OS3HYBM | E26: =VLOOKUP(D26,Sheet4!A26:B1000,2,0) -> https://dashboard.digitweblk.com/Productimages/23653.jpg | F26: =IMAGE(E26:E1024) | G26: FALSE | H26: FALSE | I26: FALSE | J26: FALSE | K26: FALSE
A27: 26 | D27: PSL4P25OS2HNBM | E27: =VLOOKUP(D27,Sheet4!A27:B1000,2,0) -> https://dashboard.digitweblk.com/Productimages/23654.jpg | F27: =IMAGE(E27:E1025) | G27: FALSE | H27: FALSE | I27: FALSE | J27: FALSE | K27: FALSE
A28: 27 | D28: PSL45P05OS2HYWH | E28: =VLOOKUP(D28,Sheet4!A28:B1000,2,0) -> https://dashboard.digitweblk.com/Productimages/23656.jpg | F28: =IMAGE(E28:E1026) | G28: FALSE | H28: FALSE | I28: FALSE | J28: FALSE | K28: FALSE
A29: 28 | D29: PSL2P15OS2HNBM | E29: =VLOOKUP(D29,Sheet4!A29:B1000,2,0) -> https://dashboard.digitweblk.com/Productimages/23655.jpg | F29: =IMAGE(E29:E1027) | G29: FALSE | H29: FALSE | I29: FALSE | J29: FALSE | K29: FALSE
A30: 29 | D30: IMACWW | E30: =VLOOKUP(D30,Sheet4!A29:B1000,2,0) -> https://dashboard.digitweblk.com/Productimages/23722.jpg | F30: =IMAGE(E30:E1028) | G30: FALSE | H30: FALSE | I30: FALSE | J30: FALSE | K30: FALSE
A31: 30 | D31: IMACRG | E31: =VLOOKUP(D31,Sheet4!A30:B1000,2,0) -> https://dashboard.digitweblk.com/Productimages/23721.jpg | F31: =IMAGE(E31:E1029) | G31: FALSE | H31: FALSE | I31: FALSE | J31: FALSE | K31: FALSE
A32: 31 | D32: IMACGR | E32: =VLOOKUP(D32,Sheet4!A31:B1000,2,0) -> https://dashboard.digitweblk.com/Productimages/23720.jpg | F32: =IMAGE(E32:E1030) | G32: FALSE | H32: FALSE | I32: FALSE | J32: FALSE | K32: FALSE
A33: 32 | D33: IMACYE | E33: =VLOOKUP(D33,Sheet4!A32:B1000,2,0) -> https://dashboard.digitweblk.com/Productimages/23719.jpg | F33: =IMAGE(E33:E1031) | G33: FALSE | H33: FALSE | I33: FALSE | J33: FALSE | K33: FALSE
A34: 33 | D34: IMACCW | E34: =VLOOKUP(D34,Sheet4!A33:B1000,2,0) -> https://dashboard.digitweblk.com/Productimages/23718.jpg | F34: =IMAGE(E34:E1032) | G34: FALSE | H34: FALSE | I34: FALSE | J34: FALSE | K34: FALSE
A35: 34 | D35: IMYE | E35: =VLOOKUP(D35,Sheet4!A34:B1000,2,0) -> https://dashboard.digitweblk.com/Productimages/23717.jpg | F35: =IMAGE(E35:E1033) | G35: FALSE | H35: FALSE | I35: FALSE | J35: FALSE | K35: FALSE
D36: WLFS220YBG | E36: =VLOOKUP(D36,Sheet4!A35:B1000,2,0) -> https://dashboard.digitweblk.com/Productimages/23846.jpg | F36: =IMAGE(E36:E1034)
E37: =VLOOKUP(D37,Sheet4!A36:B1000,2,0) -> #N/A | F37: =IMAGE(E37:E1035) -> #N/A
F38: =IMAGE(E38:E1036)
F39: =IMAGE(E39:E1037)
F40: =IMAGE(E40:E1038)
...

Sheet Container 15
A1: No | B1: ASIN | C1: eBay IDs | D1: SKU | E1: Image Link | F1: Images | G1: Varmen Confirm | H1: Adams Listing | I1: Amazon | J1: Ebay | K1: Shopify | L1: delivery date 11/03/2026 | M1: =counta(D:D)-1 -> 3 | N1: =COUNTIF(I1:I100, TRUE) -> 0 | O1: =N1/M1 -> 0
A2: 1 | D2: WLIP65UPBM | E2: =VLOOKUP(D2,Sheet4!A2:B999,2,0) -> https://dashboard.digitweblk.com/Productimages/23649.jpg | F2: =IMAGE(E2) | G2: FALSE | H2: FALSE | I2: FALSE | J2: FALSE | K2: FALSE
A3: 2 | D3: WLIP65DNBM | E3: =VLOOKUP(D3,Sheet4!A3:B999,2,0) -> https://dashboard.digitweblk.com/Productimages/23650.jpg | F3: =IMAGE(E3) | G3: FALSE | H3: FALSE | I3: FALSE | J3: FALSE | K3: FALSE
A4: 3 | D4: WLIP65DNBM | E4: =VLOOKUP(D4,Sheet4!A4:B999,2,0) -> https://dashboard.digitweblk.com/Productimages/23650.jpg | F4: =IMAGE(E4) | G4: FALSE | H4: FALSE | I4: FALSE | J4: FALSE | K4: FALSE

Sheet Container 16
A1: No | B1: ASIN | C1: eBay IDs | D1: SKU | E1: Image Link | F1: Images | G1: Varmen Confirm | H1: Adams Listing | I1: Amazon | J1: Ebay | K1: Shopify | L1: 28-03-2026 | M1: =counta(D:D)-1 -> 51 | N1: =COUNTIF(I1:I77, TRUE) -> 0 | O1: =N1/M1 -> 0
A2: 1 | D2: LSSC310BI | E2: =VLOOKUP(D2,Sheet4!A2:B977,2,0) -> https://dashboard.digitweblk.com/Productimages/23730.jpg | F2: =image(E2) | G2: FALSE | H2: TRUE | I2: FALSE | J2: FALSE | K2: FALSE
A3: 2 | D3: LSSC310GR | E3: =VLOOKUP(D3,Sheet4!A3:B977,2,0) -> https://dashboard.digitweblk.com/Productimages/23731.jpg | F3: =image(E3) | G3: FALSE | H3: TRUE | I3: FALSE | J3: FALSE | K3: FALSE
A4: 3 | D4: LSSC310GY | E4: =VLOOKUP(D4,Sheet4!A4:B977,2,0) -> https://dashboard.digitweblk.com/Productimages/23732.jpg | F4: =image(E4) | G4: FALSE | H4: TRUE | I4: FALSE | J4: FALSE | K4: FALSE
A5: 4 | D5: LSSC310RE | E5: =VLOOKUP(D5,Sheet4!A5:B977,2,0) -> https://dashboard.digitweblk.com/Productimages/23734.jpg | F5: =image(E5) | G5: FALSE | H5: TRUE | I5: FALSE | J5: FALSE | K5: FALSE
A6: 5 | D6: LSSC310OR | E6: =VLOOKUP(D6,Sheet4!A6:B977,2,0) -> https://dashboard.digitweblk.com/Productimages/23733.jpg | F6: =image(E6) | G6: FALSE | H6: TRUE | I6: FALSE | J6: FALSE | K6: FALSE
A7: 6 | D7: WSAFT200BG | E7: =VLOOKUP(D7,Sheet4!A7:B977,2,0) -> https://dashboard.digitweblk.com/Productimages/23772.jpg | F7: =image(E7) | G7: FALSE | H7: FALSE | I7: FALSE | J7: FALSE | K7: FALSE
A8: 7 | D8: WSAHQS150BG | E8: =VLOOKUP(D8,Sheet4!A8:B977,2,0) -> https://dashboard.digitweblk.com/Productimages/23773.jpg | F8: =image(E8) | G8: FALSE | H8: FALSE | I8: FALSE | J8: FALSE | K8: FALSE
A9: 8 | D9: WSACY195BG | E9: =VLOOKUP(D9,Sheet4!A9:B977,2,0) -> https://dashboard.digitweblk.com/Productimages/23779.jpg | F9: =image(E9) | G9: FALSE | H9: FALSE | I9: FALSE | J9: FALSE | K9: FALSE
A10: 9 | D10: LSACY195BG | E10: =VLOOKUP(D10,Sheet4!A10:B977,2,0) -> https://dashboard.digitweblk.com/Productimages/23689.jpg | F10: =image(E10) | G10: FALSE | H10: TRUE | I10: FALSE | J10: FALSE | K10: FALSE
A11: 10 | D11: LSAFT200BG | E11: =VLOOKUP(D11,Sheet4!A11:B977,2,0) -> https://dashboard.digitweblk.com/Productimages/23687.png | F11: =image(E11) | G11: FALSE | H11: TRUE | I11: FALSE | J11: FALSE | K11: FALSE
A12: 11 | D12: WLWOHTBM | E12: =VLOOKUP(D12,Sheet4!A12:B977,2,0) -> https://dashboard.digitweblk.com/Productimages/23769.jpg | F12: =image(E12) | G12: FALSE | H12: TRUE | I12: FALSE | J12: FALSE | K12: FALSE
A13: 12 | D13: WLWOFTWO | E13: =VLOOKUP(D13,Sheet4!A13:B977,2,0) -> https://dashboard.digitweblk.com/Productimages/23770.jpg | F13: =image(E13) | G13: FALSE | H13: TRUE | I13: FALSE | J13: FALSE | K13: FALSE
A14: 13 | D14: WSCYMUBG | E14: =VLOOKUP(D14,Sheet4!A14:B977,2,0) -> https://dashboard.digitweblk.com/Productimages/23768.jpg | F14: =image(E14) | G14: FALSE | H14: FALSE | I14: FALSE | J14: FALSE | K14: FALSE
A15: 14 | D15: WSCYMUBM | E15: =VLOOKUP(D15,Sheet4!A15:B977,2,0) -> https://dashboard.digitweblk.com/Productimages/23767.jpg | F15: =image(E15) | G15: FALSE | H15: FALSE | I15: FALSE | J15: FALSE | K15: FALSE
A16: 15 | D16: WS2HTBMYB | E16: =VLOOKUP(D16,Sheet4!A16:B977,2,0) -> https://dashboard.digitweblk.com/Productimages/23780.jpg | F16: =image(E16) | G16: FALSE | H16: FALSE | I16: FALSE | J16: FALSE | K16: FALSE
A17: 15 | D17: PHIFT1PCRCH | E17: =VLOOKUP(D17,Sheet4!A17:B977,2,0) -> https://dashboard.digitweblk.com/Productimages/23774.png | F17: =image(E17) | G17: FALSE | H17: FALSE | I17: FALSE | J17: FALSE | K17: FALSE
A18: 17 | D18: PHIFT1PBRYB | E18: =VLOOKUP(D18,Sheet4!A18:B977,2,0) -> https://dashboard.digitweblk.com/Productimages/23771.png | F18: =image(E18) | G18: FALSE | H18: FALSE | I18: FALSE | J18: FALSE | K18: FALSE
A19: 18 | D19: PHIFT1PBRBM | E19: =VLOOKUP(D19,Sheet4!A19:B977,2,0) -> https://dashboard.digitweblk.com/Productimages/23775.png | F19: =image(E19) | G19: FALSE | H19: FALSE | I19: FALSE | J19: FALSE | K19: FALSE
A20: 19 | D20: LHIFTE27BM | E20: =VLOOKUP(D20,Sheet4!A20:B977,2,0) -> https://dashboard.digitweblk.com/Productimages/23777.jpg | F20: =image(E20) | G20: FALSE | H20: FALSE | I20: FALSE | J20: FALSE | K20: FALSE
A21: 20 | D21: LHIFTE27CH | E21: =VLOOKUP(D21,Sheet4!A21:B977,2,0) -> https://dashboard.digitweblk.com/Productimages/23778.jpg | F21: =image(E21) | G21: FALSE | H21: FALSE | I21: FALSE | J21: FALSE | K21: FALSE
A22: 21 | D22: LHIFTE27YB | E22: =VLOOKUP(D22,Sheet4!A22:B977,2,0) -> https://dashboard.digitweblk.com/Productimages/23776.jpg | F22: =image(E22) | G22: FALSE | H22: FALSE | I22: FALSE | J22: FALSE | K22: FALSE
A23: 22 | D23: CRSP80303BM | E23: =VLOOKUP(D23,Sheet4!A23:B977,2,0) -> https://dashboard.digitweblk.com/Productimages/23747.jpg | F23: =image(E23) | G23: FALSE | H23: FALSE | I23: FALSE | J23: FALSE | K23: FALSE
A24: 23 | D24: CRSP80304BM | E24: =VLOOKUP(D24,Sheet4!A24:B977,2,0) -> https://dashboard.digitweblk.com/Productimages/23753.jpg | F24: =image(E24) | G24: FALSE | H24: FALSE | I24: FALSE | J24: FALSE | K24: FALSE
A25: 24 | D25: CRSP80303CO | E25: =VLOOKUP(D25,Sheet4!A25:B977,2,0) -> https://dashboard.digitweblk.com/Productimages/23749.jpg | F25: =image(E25) | G25: FALSE | H25: FALSE | I25: FALSE | J25: FALSE | K25: FALSE
A26: 25 | D26: CRSP80305BM | E26: =VLOOKUP(D26,Sheet4!A26:B977,2,0) -> https://dashboard.digitweblk.com/Productimages/23757.jpg | F26: =image(E26) | G26: FALSE | H26: FALSE | I26: FALSE | J26: FALSE | K26: FALSE
A27: 26 | D27: CRSP80305YB | E27: =VLOOKUP(D27,Sheet4!A27:B977,2,0) -> https://dashboard.digitweblk.com/Productimages/23758.jpg | F27: =image(E27) | G27: FALSE | H27: FALSE | I27: FALSE | J27: FALSE | K27: FALSE
A28: 27 | D28: CRSP80303CH | E28: =VLOOKUP(D28,Sheet4!A28:B977,2,0) -> https://dashboard.digitweblk.com/Productimages/23748.jpg | F28: =image(E28) | G28: FALSE | H28: TRUE | I28: FALSE | J28: FALSE | K28: FALSE
A29: 28 | D29: CRSP80303YB | E29: =VLOOKUP(D29,Sheet4!A29:B977,2,0) -> https://dashboard.digitweblk.com/Productimages/23750.jpg | F29: =image(E29) | G29: FALSE | H29: FALSE | I29: FALSE | J29: FALSE | K29: FALSE
A30: 29 | D30: CRSP80305CH | E30: =VLOOKUP(D30,Sheet4!A30:B977,2,0) -> https://dashboard.digitweblk.com/Productimages/23756.jpg | F30: =image(E30) | G30: FALSE | H30: FALSE | I30: FALSE | J30: FALSE | K30: FALSE
A31: 30 | D31: CRSP80305CO | E31: =VLOOKUP(D31,Sheet4!A31:B977,2,0) -> https://dashboard.digitweblk.com/Productimages/23755.jpg | F31: =image(E31) | G31: FALSE | H31: FALSE | I31: FALSE | J31: FALSE | K31: FALSE
A32: 31 | D32: CRSP80303SN | E32: =VLOOKUP(D32,Sheet4!A32:B977,2,0) -> https://dashboard.digitweblk.com/Productimages/23751.jpg | F32: =image(E32) | G32: TRUE | H32: FALSE | I32: FALSE | J32: FALSE | K32: FALSE
A33: 1 | D33: CRSP60603BM | E33: =VLOOKUP(D33,Sheet4!A33:B977,2,0) -> https://dashboard.digitweblk.com/Productimages/23752.png | F33: =image(E33) | G33: FALSE | H33: FALSE | I33: FALSE | J33: FALSE | K33: FALSE
A34: 1 | D34: CRSP60605BM | E34: =VLOOKUP(D34,Sheet4!A34:B977,2,0) -> https://dashboard.digitweblk.com/Productimages/23759.jpg | F34: =image(E34) | G34: FALSE | H34: FALSE | I34: FALSE | J34: FALSE | K34: FALSE
A35: 1 | D35: CRSP60605WH | E35: =VLOOKUP(D35,Sheet4!A35:B977,2,0) -> https://dashboard.digitweblk.com/Productimages/23760.jpg | F35: =image(E35) | G35: FALSE | H35: FALSE | I35: FALSE | J35: FALSE | K35: FALSE
A36: 1 | D36: CRSP60603WH | E36: =VLOOKUP(D36,Sheet4!A36:B977,2,0) -> https://dashboard.digitweblk.com/Productimages/23761.jpg | F36: =image(E36) | G36: FALSE | H36: FALSE | I36: FALSE | J36: FALSE | K36: FALSE
A37: 1 | D37: CRSP60601BM | E37: =VLOOKUP(D37,Sheet4!A37:B977,2,0) -> https://dashboard.digitweblk.com/Productimages/23762.jpg | F37: =image(E37) | G37: TRUE | H37: FALSE | I37: FALSE | J37: FALSE | K37: TRUE
A38: 1 | D38: CRSP80305WH | E38: =VLOOKUP(D38,Sheet4!A38:B977,2,0) -> https://dashboard.digitweblk.com/Productimages/23754.jpg | F38: =image(E38) | G38: FALSE | H38: FALSE | I38: FALSE | J38: FALSE | K38: FALSE
A39: 1 | D39: CRSP80305SN | E39: =VLOOKUP(D39,Sheet4!A39:B977,2,0) -> https://dashboard.digitweblk.com/Productimages/23763.jpg | F39: =image(E39) | G39: FALSE | H39: FALSE | I39: FALSE | J39: FALSE | K39: FALSE
A40: 1 | D40: CRSP80303WH | E40: =VLOOKUP(D40,Sheet4!A40:B977,2,0) -> https://dashboard.digitweblk.com/Productimages/23764.jpg | F40: =image(E40) | G40: FALSE | H40: FALSE | I40: FALSE | J40: FALSE | K40: FALSE
...

Sheet Container 17

Sheet Sheet4
A1: SKU | B1: Image URL | C1: Stock(Whole) | D1: Supplier | E1: Sales* | F1: Month of Supply* | G1: Stock Transfer* | H1: In Order | I1: View
A2: IMCW | B2: https://dashboard.digitweblk.com/Productimages/3878.png | C2: 10270 | D2: Led Induction module supplier | E2: 17252 | F2: 2 | G2: 0 | H2: Container 04 2024 - order - 12000Container 13 2025 - order - 15000 | I2: CBM ViewIn Shipping
A3: RPR44WH | B3: http://dashboard.digitweblk.com/Productimages/RPR44WH.jpg | C3: 22301 | D3: Ceiling rose guy | E3: 13933 | F3: 3 | G3: 9160 | H3: Container 16 2025 - order - 40000Container 14 2025-bal - order - 40000Container 01 2026 - order - 20000 | I3: CBM ViewIn Shipping
A4: LDMST64E274 | B4: https://dashboard.digitweblk.com/Productimages/846.jpg | C4: 26726 | D4: Bulbs supplier | E4: 12114 | F4: 6 | G4: 389 | H4: Container 14 2025 - order - 5000Container 16 2025 - order - 10000Container 01 2026 - order - 5000Container 04 2026 - order - 5000 | I4: CBM ViewIn Shipping
A5: SCRN70BM | B5: http://dashboard.digitweblk.com/Productimages/SCRN70BM.jpg | C5: 9180 | D5: Ceiling rose guy | E5: 3886 | F5: 4 | G5: 2527 | H5: Container 16 2025 - order - 5500Container 01 2026 - order - 5500 | I5: CBM ViewIn Shipping
A6: CRSF100BM | B6: http://dashboard.digitweblk.com/Productimages/1355.jpg | C6: 12890 | D6: Ceiling rose Lady Supplier | E6: 3770 | F6: 9 | G6: 671 | H6: Container 16 2025 - order - 3000Container 01 2026 - order - 3000 | I6: CBM ViewIn Shipping
A7: IMRG | B7: https://dashboard.digitweblk.com/Productimages/3876.jpg | C7: 17996 | D7: Led Induction module supplier | E7: 3024 | F7: 18 | G7: 0 | H7: Container 13 2025 - order - 15000 | I7: CBM ViewIn Shipping
A8: IMWW | B8: https://dashboard.digitweblk.com/Productimages/22847.jpg | C8: 7670 | D8: Led Induction module supplier | E8: 2680 | F8: 9 | G8: 0 | H8: Container 13 2025 - order - 15000 | I8: CBM ViewIn Shipping
A9: LDMST64E278 | B9: https://dashboard.digitweblk.com/Productimages/3996.jpg | C9: 4553 | D9: Bulbs supplier | E9: 2394 | F9: 5 | G9: 286 | H9: Container 14 2025 - order - 1500Container 16 2025 - order - 2000Container 04 2026 - order - 1000 | I9: CBM ViewIn Shipping
A10: LDMG95E278 | B10: http://dashboard.digitweblk.com/Productimages/LDMG95E278.jpg | C10: 3984 | D10: Bulbs supplier | E10: 2166 | F10: 5 | G10: 448 | H10: Container 14 2025 - order - 2500Container 16 2025 - order - 3500Container 04 2026 - order - 500 | I10: CBM ViewIn Shipping
A11: MBEX1730BM | B11: https://dashboard.digitweblk.com/Productimages/21986.jpg | C11: 0 | D11: GH - 07 Mail bag Supplier | E11: 2000 | F11: 0 | G11: 0 | I11: CBM ViewAdd To Supply
A12: IMBL | B12: https://dashboard.digitweblk.com/Productimages/3873.jpg | C12: 1506 | D12: Led Induction module supplier | E12: 1930 | F12: 2 | G12: 0 | I12: CBM ViewAdd To Supply
A13: CMWH | B13: https://dashboard.digitweblk.com/Productimages/4056.jpg | C13: 12160 | D13: Led Induction module supplier | E13: 1920 | F13: 19 | G13: 0 | I13: CBM ViewAdd To Supply
A14: PHFMSH2BRYB | B14: https://dashboard.digitweblk.com/Productimages/23087.jpg | C14: 1665 | D14: Assembling 2 Supplier | E14: 1678 | F14: 3 | G14: 18 | H14: Container 14 2025 - order - 2500Container 16 2025 - order - 2000Container 01 2026 - order - 2000 | I14: CBM ViewIn Shipping
A15: LDMG95E274 | B15: http://dashboard.digitweblk.com/Productimages/LDMG95E274.jpg | C15: 3864 | D15: Bulbs supplier | E15: 1618 | F15: 4 | G15: 1038 | H15: Container 14 2025 - order - 2000Container 16 2025 - order - 2000Container 01 2026 - order - 1000Container 04 2026 - order - 500 | I15: CBM ViewIn Shipping
A16: LDMC35E144 | B16: http://dashboard.digitweblk.com/Productimages/LDMC35E144.jpg | C16: 2508 | D16: Bulbs supplier | E16: 1523 | F16: 5 | G16: 0 | H16: Container 16 2025 - order - 1000Container 01 2026 - order - 1000Container 04 2026 - order - 1500 | I16: CBM ViewIn Shipping
A17: LDMA60E274WW | B17: http://dashboard.digitweblk.com/Productimages/LDMA60E274WW.jpg | C17: 289 | D17: Bulbs supplier | E17: 1383 | F17: 1 | G17: 16 | H17: Container 14 2025 - order - 1000Container 16 2025 - order - 1000Container 01 2026 - order - 1500Container 04 2026 - order - 2000 | I17: CBM ViewIn Shipping
A18: CO232AOR | B18: http://dashboard.digitweblk.com/Productimages/2slco.jpg | C18: 0 | D18: Connectors supplier | E18: 1285 | F18: 0 | G18: 0 | H18: Container 04 2026 - order - 5000 | I18: CBM ViewIn Shipping
A19: LDMT45E274 | B19: http://dashboard.digitweblk.com/Productimages/LDMT45E274.jpg | C19: 712 | D19: Bulbs supplier | E19: 1196 | F19: 2 | G19: 222 | H19: Container 16 2025 - order - 2000Container 01 2026 - order - 1500Container 04 2026 - order - 1500 | I19: CBM ViewIn Shipping
A20: STKP48EBR | B20: https://dashboard.digitweblk.com/Productimages/22264.jpg | C20: -2 | D20: GH - 31 Cartoon Tape Supplier | E20: 1163 | F20: 0 | G20: 45 | H20: GH Container 2026 - order - 8000 | I20: CBM ViewIn Shipping
A21: WCDCBM | B21: https://dashboard.digitweblk.com/Productimages/2013.jpg | C21: 4501 | D21: Different type wire cage supplier | E21: 1125 | F21: 14 | G21: 154 | H21: Container 16 2025 - shipping - 1400 | I21: CBM ViewIn Shipping
A22: IMRE | B22: https://dashboard.digitweblk.com/Productimages/3875.jpg | C22: 34 | D22: Led Induction module supplier | E22: 1110 | F22: 0 | G22: 0 | H22: Container 04 2024 - order - 7500Container 13 2025 - order - 10000 | I22: CBM ViewIn Shipping
A23: SCRN70YB | B23: http://dashboard.digitweblk.com/Productimages/SCRN70YB.jpg | C23: 1070 | D23: Ceiling rose guy | E23: 1108 | F23: 2 | G23: 183 | H23: Container 16 2025 - order - 2000Container 14 2025-bal - order - 1500Container 01 2026 - order - 2000 | I23: CBM ViewIn Shipping
A24: CO332AGY | B24: http://dashboard.digitweblk.com/Productimages/3SLGO.jpg | C24: 740 | D24: Connectors supplier | E24: 1103 | F24: 1 | G24: 500 | H24: Container 04 2026 - order - 5000 | I24: CBM ViewIn Shipping
A25: MBEX1730WH | B25: https://dashboard.digitweblk.com/Productimages/22010.jpg | C25: 4440 | D25: GH - 07 Mail bag Supplier | E25: 1020 | F25: 13 | G25: 0 | I25: CBM ViewAdd To Supply
A26: PHSHF1PBRYB | B26: https://dashboard.digitweblk.com/Productimages/22789.jpg | C26: 890 | D26: Assembling 2 Supplier | E26: 1019 | F26: 3 | G26: 40 | H26: Container 14 2025 - order - 500Container 01 2026 - order - 1000 | I26: CBM ViewIn Shipping
A27: LHNSE27YB | B27: http://dashboard.digitweblk.com/Productimages/STHRLNYBS.jpg | C27: 1381 | D27: Cable supplier | E27: 1017 | F27: 3 | G27: 427 | H27: Container 16 2025 - order - 2000 | I27: CBM ViewIn Shipping
A28: PHSH1PBRYB | B28: http://dashboard.digitweblk.com/Productimages/CS-STHRRYBS.jpg | C28: 4304 | D28: Assembling 2 Supplier | E28: 919 | F28: 14 | G28: 20 | I28: CBM ViewAdd To Supply
A29: RWWD | B29: http://dashboard.digitweblk.com/Productimages/RWWD.jpg | C29: 584 | D29: No CBM Data | E29: 896 | F29: 2 | G29: 0 | I29: CBM ViewAdd To Supply
A30: RWWP | B30: https://dashboard.digitweblk.com/Productimages/15903.jpg | C30: 445 | D30: No CBM Data | E30: 888 | F30: 2 | G30: 0 | I30: CBM ViewAdd To Supply
A31: LDMG80E274 | B31: http://dashboard.digitweblk.com/Productimages/LDMG80E274.jpg | C31: 865 | D31: Bulbs supplier | E31: 866 | F31: 3 | G31: 127 | H31: Container 16 2025 - order - 1000Container 01 2026 - order - 1000Container 04 2026 - order - 1000 | I31: CBM ViewIn Shipping
A32: CODL232AGY | B32: http://dashboard.digitweblk.com/Productimages/2GOSLDSCCR.jpg | C32: 2884 | D32: Connectors supplier | E32: 857 | F32: 10 | G32: 0 | H32: Container 04 2026 - order - 2000 | I32: CBM ViewIn Shipping
A33: PHFMHT2BRBM | B33: https://dashboard.digitweblk.com/Productimages/23090.jpg | C33: 696 | D33: Assembling 2 Supplier | E33: 850 | F33: 2 | G33: 0 | H33: Container 16 2025 - order - 800Container 01 2026 - order - 2000 | I33: CBM ViewIn Shipping
A34: CO232AGY | B34: http://dashboard.digitweblk.com/Productimages/2SLGO.jpg | C34: 438 | D34: Connectors supplier | E34: 838 | F34: 2 | G34: 0 | H34: Container 04 2026 - order - 3000 | I34: CBM ViewIn Shipping
A35: CBFA200BM | B35: https://dashboard.digitweblk.com/Productimages/22023.jpg | C35: 23080 | D35: Ceiling rose guy | E35: 820 | F35: 52 | G35: 500 | I35: CBM ViewAdd To Supply
A36: IMGR | B36: https://dashboard.digitweblk.com/Productimages/3874.jpg | C36: 10873 | D36: Led Induction module supplier | E36: 810 | F36: 40 | G36: 0 | I36: CBM ViewAdd To Supply
A37: LHNSE27BM | B37: http://dashboard.digitweblk.com/Productimages/STHRLNMBK.jpg | C37: 1320 | D37: Cable supplier | E37: 784 | F37: 4 | G37: 327 | H37: Container 16 2025 - order - 2000 | I37: CBM ViewIn Shipping
A38: LDMA60E278WW | B38: https://dashboard.digitweblk.com/Productimages/4228.jpg | C38: 676 | D38: Bulbs supplier | E38: 779 | F38: 3 | G38: 8 | H38: Container 01 2026 - order - 1500Container 04 2026 - order - 1500 | I38: CBM ViewIn Shipping
A39: LDMG125E278 | B39: http://dashboard.digitweblk.com/Productimages/LDMG125E278.jpg | C39: 2804 | D39: Bulbs supplier | E39: 767 | F39: 7 | G39: 359 | H39: Container 14 2025 - order - 500Container 16 2025 - order - 500Container 01 2026 - order - 500Container 04 2026 - order - 500 | I39: CBM ViewIn Shipping
A40: LDCWA60HB229 | B40: https://dashboard.digitweblk.com/Productimages/23463.jpg | C40: 3669 | D40: New A60 Bulbs supplier | E40: 755 | F40: 15 | G40: 0 | H40: Container 14 2025 - order - 2000 | I40: CBM ViewIn Shipping
...
